Traceback (most recent call last):
  File "/usr/local/lib/python3.10/dist-packages/wandb/sdk/wandb_config.py", line 165, in __getattr__
    return self.__getitem__(key)
  File "/usr/local/lib/python3.10/dist-packages/wandb/sdk/wandb_config.py", line 130, in __getitem__
    return self._items[key]
KeyError: 'batch_size'

The above exception was the direct cause of the following exception:

Traceback (most recent call last):
  File "/4TBHD/ishaan/da6401_assignment2/sweep_train.py", line 62, in <module>
    train_wandb()
  File "/4TBHD/ishaan/da6401_assignment2/sweep_train.py", line 24, in train_wandb
    batch_size=config.batch_size,
  File "/usr/local/lib/python3.10/dist-packages/wandb/sdk/wandb_config.py", line 167, in __getattr__
    raise AttributeError(
AttributeError: <class 'wandb.sdk.wandb_config.Config'> object has no attribute 'batch_size'
Traceback (most recent call last):
  File "/usr/local/lib/python3.10/dist-packages/wandb/sdk/wandb_config.py", line 165, in __getattr__
    return self.__getitem__(key)
  File "/usr/local/lib/python3.10/dist-packages/wandb/sdk/wandb_config.py", line 130, in __getitem__
    return self._items[key]
KeyError: 'batch_size'

The above exception was the direct cause of the following exception:

Traceback (most recent call last):
  File "/4TBHD/ishaan/da6401_assignment2/sweep_train.py", line 62, in <module>
    train_wandb()
  File "/4TBHD/ishaan/da6401_assignment2/sweep_train.py", line 24, in train_wandb
    batch_size=config.batch_size,
  File "/usr/local/lib/python3.10/dist-packages/wandb/sdk/wandb_config.py", line 167, in __getattr__
    raise AttributeError(
AttributeError: <class 'wandb.sdk.wandb_config.Config'> object has no attribute 'batch_size'
